2025-05-31 18:49:17,470 | INFO | cache_base | The cache server is running live at host : localhost and port : 6379
2025-05-31 18:49:17,471 | INFO | cache_base | Server has been shut down
2025-05-31 18:49:23,414 | INFO | cache_base | The cache server is running live at host : localhost and port : 6379
2025-05-31 18:49:23,415 | INFO | cache_base | Server has been shut down
2025-05-31 18:49:24,290 | INFO | cache_base | The cache server is running live at host : localhost and port : 6379
2025-05-31 18:49:24,290 | INFO | cache_base | Server has been shut down
2025-05-31 18:49:39,993 | INFO | cache_base | The cache server is running live at host : localhost and port : 6379
2025-05-31 18:49:39,993 | INFO | cache_base | Server has been shut down
2025-05-31 18:52:14,232 | INFO | cache_base | The cache server is running live at host : localhost and port : 6379
2025-05-31 18:52:23,939 | ERROR | cache_base | Shutting Down the server
Traceback (most recent call last):
  File "/home/psychohunter/Documents/cc/key_value_store/server/server.py", line 41, in start
    client_socket,addr = self.server_socket.accept()
                         ^^^^^^^^^^^^^^^^^^^^^^^^^^^
  File "/usr/lib/python3.12/socket.py", line 295, in accept
    fd, addr = self._accept()
               ^^^^^^^^^^^^^^
KeyboardInterrupt
2025-05-31 18:52:33,943 | INFO | cache_base | Server has been shut down
2025-05-31 18:59:06,549 | INFO | cache_base | The cache server is running live at host : localhost and port : 6379
2025-05-31 18:59:16,674 | INFO | cache_base | New client connected from address ('127.0.0.1', 41098)
2025-05-31 18:59:32,821 | ERROR | cache_base | ERROR IN COMMAND get client :('127.0.0.1', 41098)
2025-05-31 18:59:35,037 | INFO | cache_base | Client ('127.0.0.1', 41098) disconnected from server
2025-05-31 18:59:44,056 | INFO | cache_base | New client connected from address ('127.0.0.1', 59474)
2025-05-31 19:00:06,101 | INFO | cache_base | Client ('127.0.0.1', 59474) disconnected from server
2025-05-31 19:00:37,832 | ERROR | cache_base | Shutting Down the server
Traceback (most recent call last):
  File "/home/psychohunter/Documents/cc/key_value_store/server/server.py", line 41, in start
    client_socket,addr = self.server_socket.accept()
                         ^^^^^^^^^^^^^^^^^^^^^^^^^^^
  File "/usr/lib/python3.12/socket.py", line 295, in accept
    fd, addr = self._accept()
               ^^^^^^^^^^^^^^
KeyboardInterrupt
2025-06-09 23:57:33,506 | INFO | cache_base | The cache server is running live at host : localhost and port : 6379
2025-06-09 23:57:42,871 | INFO | cache_base | New client connected from address ('127.0.0.1', 46934)
2025-06-09 23:57:49,280 | INFO | cache_base | OK
2025-06-09 23:57:51,752 | INFO | cache_base | a
2025-06-09 23:57:55,944 | INFO | cache_base | ERROR: Not a valid command
2025-06-09 23:57:55,945 | ERROR | cache_base | ERROR: Not a valid command client :('127.0.0.1', 46934)
2025-06-09 23:58:01,552 | INFO | cache_base | 1
2025-06-09 23:58:46,656 | ERROR | cache_base | Shutting Down the server
Traceback (most recent call last):
  File "/home/psychohunter/Documents/cc/key_value_store/server/server.py", line 41, in start
    client_socket,addr = self.server_socket.accept()
                         ^^^^^^^^^^^^^^^^^^^^^^^^^^^
  File "/usr/lib/python3.12/socket.py", line 295, in accept
    fd, addr = self._accept()
               ^^^^^^^^^^^^^^
KeyboardInterrupt
2025-06-09 23:59:20,593 | INFO | cache_base | The cache server is running live at host : localhost and port : 6379
2025-06-09 23:59:25,805 | INFO | cache_base | New client connected from address ('127.0.0.1', 51514)
2025-06-09 23:59:27,507 | INFO | cache_base | OK
2025-06-09 23:59:28,827 | INFO | cache_base | a
2025-06-09 23:59:30,627 | INFO | cache_base | 1
2025-06-09 23:59:46,012 | INFO | cache_base | 1749493786012-0
2025-06-09 23:59:55,445 | INFO | cache_base | 1749493795445-0
2025-06-10 00:00:02,277 | INFO | cache_base | [['1749493786012-0', ['name', 'tutan', 'age', 20]], ['1749493795445-0', ['name', 'haristwa', 'age', 19]]]
2025-06-10 00:00:04,294 | INFO | cache_base | Client ('127.0.0.1', 51514) disconnected from server
2025-06-10 00:00:14,625 | ERROR | cache_base | Shutting Down the server
Traceback (most recent call last):
  File "/home/psychohunter/Documents/cc/key_value_store/server/server.py", line 41, in start
    client_socket,addr = self.server_socket.accept()
                         ^^^^^^^^^^^^^^^^^^^^^^^^^^^
  File "/usr/lib/python3.12/socket.py", line 295, in accept
    fd, addr = self._accept()
               ^^^^^^^^^^^^^^
KeyboardInterrupt
